Workbook

Sheet Read Me
A1: Home Credit LAP voice agent: test tracker
A3: Status
A4: Results for T01 to T55 are filled in from the uploaded transcripts. Hindi and language tests (T56 to T61) were removed.
A5: Recording and transcript links are still blank. Add them once the files are on Google Drive.
A7: How to use
A8: 1. Yellow cells are yours to edit: Actual result, Status, links and notes.
A9: 2. Status has a dropdown: Not run, Pass, Fail, Retest. Colours change on their own.
A10: 3. After any prompt change, set the related tests to Retest and run them again.
A11: 4. The Summary tab updates by itself. The Findings tab lists what to fix in the prompt.
A13: Assumptions
A14: T21: declining 75 lakh is treated as not eligible. The assignment does not say what happens, so this is an interpretation.
A15: T26 to T30: the agent never asks about an existing loan itself, it only reacts if the customer mentions it.
... A18: Retest means the transcript did not match the script, or the result could not be judged from the transcript.

Sheet Test Sheet
A1: ID | B1: Priority | C1: Category | D1: Scenario | E1: Language | F1: What to say (script) | G1: Expected behaviour | H1: Expected outcome | I1: Actual result | J1: Status | K1: Recording link | L1: Transcript link | M1: Notes / fix
A2: T01 | B2: High | C2: Happy path | D2: Perfect customer | E2: English | F2: Residential flat. Sole owner. Originals at home. Need 50 lakh. Salaried, salary comes to bank. Worth about 1 crore. 10 years. | G2: All 7 asked in order, none repeated, then handoff line mentioning senior expert, interest rate and next steps. | H2: Handoff to senior expert | I2: Passed. All 7 asked in order, handoff given after all answers. | J2: Pass | K2: https://drive.google.com/file/d/15hVILnzt2CagjZZkpX0Mjw69LrDHMgUw/view?usp=drive_link | L2: https://docs.google.com/document/d/1S8WNyhzvX1kVpJm96AMuoLYEKadTeVy5/edit?usp=drive_link&ouid=116177678959615855064&rtpof=true&sd=true | M2: Wrong file or wrong scenario. Re-run with residential flat, 50 lakh, salaried, 1 crore, 10 years.
A3: T02 | B3: High | C3: Happy path | D3: Commercial property, self-employed, bank income | E3: English | F3: It's a shop. Only me. Papers are at home. 40 lakh. I run a business, money comes to my bank. Maybe 80 lakh. 8 years. | G3: Accepts commercial and self-employed. Handoff. | H3: Handoff to senior expert | I3: All 7 captured in order. Re-asked ownership after a cut-off answer. Handoff given. | J3: Pass | K3: https://drive.google.com/file/d/1Iy9WTqpx5N6Uh5t14HF-2JnM-rQRxvUq/view?usp=drive_link | L3: https://docs.google.com/document/d/1S8WNyhzvX1kVpJm96AMuoLYEKadTeVy5/edit?usp=drive_link&ouid=116177678959615855064&rtpof=true&sd=true
A4: T03 | B4: Medium | C4: Happy path | D4: Industrial property | E4: English | F4: It's a small factory. Sole owner. Originals available. 60 lakh. Self-employed, bank income. 1.5 crore. 12 years. | G4: Accepts industrial. Handoff. | H4: Handoff to senior expert | I4: Industrial accepted. Loan 1.52 crore confirmed, 75 lakh offered, customer said 'Okay'. Handoff. | J4: Pass | K4: https://drive.google.com/file/d/1mzGNs9DfvR8EuCMoMiEIc6fXf3DcjV8Y/view?usp=drive_link | L4: https://docs.google.com/document/d/1ZygGItqPOs_kQSu5mDbBJVStuiT61313/edit?usp=drive_link&ouid=116177678959615855064&rtpof=true&sd=true | M4: 'Okay' was a weak yes to the 75 lakh offer. Fine, but not an explicit confirmation.
A5: T04 | B5: High | C5: Happy path | D5: Joint ownership must not disqualify | E5: English | F5: Residential house. Jointly owned with my brother. Rest of answers all valid. | G5: Treats joint ownership as eligible. Handoff. | H5: Handoff to senior expert | I5: Joint ownership accepted. Handoff. | J5: Pass | K5: https://drive.google.com/file/d/1YJeXuTJs6tD3chJW4LcAUmrnxy1pv26Z/view?usp=drive_link | L5: https://docs.google.com/document/d/1s1RVZNlVBQXJAIHy6jk_2qYe157dLcEa/edit?usp=drive_link&ouid=116177678959615855064&rtpof=true&sd=true | M5: Customer said 'Seventy' with no unit and agent accepted it without confirming lakh.
A6: T05 | B6: High | C6: Boundary | D6: Loan exactly 75 lakh, tenure exactly 3 years | E6: English | F6: Residential, sole, originals available, exactly 75 lakh, salaried bank, 1 crore, 3 years. | G6: 75 lakh and 3 years are both accepted. Handoff. | H6: Handoff to senior expert | I6: 75 lakh and 3 years accepted. Handoff. | J6: Pass | K6: https://drive.google.com/file/d/1bDaQQZi-15G7v7ce2y3lFhgG4XoQjqYb/view?usp=drive_link | L6: https://docs.google.com/document/d/1CSsCTQBaRSC8j4sJuzHchBN3xrHK2x3O/edit?usp=drive_link&ouid=116177678959615855064&rtpof=true&sd=true
A7: T06 | B7: High | C7: Boundary | D7: Tenure exactly 15 years | E7: English | F7: All valid answers, tenure 15 years. | G7: 15 years is accepted. Handoff. | H7: Handoff to senior expert | I7: 15 years accepted. Handoff. Handled 'By the way' interruption. | J7: Pass | K7: https://drive.google.com/file/d/1ENnI2MaaL-MRzEJgQ_jkFoPzakXB7p0K/view?usp=drive_link | L7: https://docs.google.com/document/d/1onCp6LkHrFi_zoKL5p9JfgPgQFhRlRB9/edit?usp=drive_link&ouid=116177678959615855064&rtpof=true&sd=true
A8: T07 | B8: High | C8: Disqualify | D8: Agricultural property | E8: English | F8: It's agricultural land. | G8: Polite not-eligible message right away. No more questions. | H8: Polite end: not eligible | I8: Rejected right after 'agricultural'. No more questions. | J8: Pass | K8: https://drive.google.com/file/d/1GBBNu45m3H8HuuiEps5kS2WtCh_664so/view?usp=drive_link | L8: https://docs.google.com/document/d/1dIZ6oQz4pDksdbbWjNLxQGfchsTUPlh5/edit?usp=drive_link&ouid=116177678959615855064&rtpof=true&sd=true
A9: T08 | B9: High | C9: Disqualify | D9: Salaried but paid in cash | E9: English | F9: Salaried, but my salary comes in cash. | G9: Not eligible. Ends call. | H9: Polite end: not eligible | I9: Re-asked unclear income, customer said cash. Rejected. | J9: Pass | K9: https://drive.google.com/file/d/1nmAhmcYP2vI4YNy9-u3Qnro3GkK-uyE8/view?usp=drive_link | L9: https://docs.google.com/document/d/1U8naQTwKgbpsC1WiwtFfghlqK_BR95t_/edit?usp=drive_link&ouid=116177678959615855064&rtpof=true&sd=true
A10: T09 | B10: High | C10: Disqualify | D10: Self-employed, cash income | E10: English | F10: I run a shop and everything is in cash. | G10: Not eligible. Ends call. | H10: Polite end: not eligible | I10: Uploaded transcript is the T10 call (photocopies), not self-employed cash. | J10: Pass | K10: https://drive.google.com/file/d/1nGlVwFmGwmXG-ZZVwz6-k70Sw9kljfJ4/view?usp=sharing | L10: https://docs.google.com/document/d/1pAVcf0H99Y8GBf2F-N_-0ucm6Kzaw4jr/edit?usp=drive_link&ouid=116177678959615855064&rtpof=true&sd=true | M10: T09 and T10 transcripts are identical. Re-run T09 as self-employed with cash income.
A11: T10 | B11: High | C11: Disqualify | D11: Only photocopies of documents | E11: English | F11: I only have photocopies. | G11: Not eligible. Ends call. | H11: Polite end: not eligible | I11: Photocopies only. Rejected. | J11: Pass | K11: https://drive.google.com/file/d/10DF2Xzy13mKzUals04DM8glUMyTMh_hH/view?usp=drive_link | L11: https://docs.google.com/document/d/1mDGjL_fhBYz9QVv2rQNqUan575nD4KLN/edit?usp=drive_link&ouid=116177678959615855064&rtpof=true&sd=true
A12: T11 | B12: High | C12: Disqualify | D12: Documents lost | E12: English | F12: I lost the original papers. | G12: Not eligible. Ends call. | H12: Polite end: not eligible | I12: Clarified 'Resident still' as house. Lost originals. Rejected. | J12: Pass | K12: https://drive.google.com/file/d/1knbonPdsTDNxVad3YxAx71QNpdVYMe2c/view?usp=drive_link | L12: https://docs.google.com/document/d/1XD9u4vswHDl16C5uNrz1uPAiaw20tQeg/edit?usp=drive_link&ouid=116177678959615855064&rtpof=true&sd=true
A13: T12 | B13: High | C13: Disqualify | D13: Tenure 2 years | E13: English | F13: Two years. | G13: Not eligible. Ends call. | H13: Polite end: not eligible | I13: Rejected for tenure under 3 years. | J13: Pass | K13: https://drive.google.com/file/d/1gdH61fBxgnD9TbuQeJtSXj6GlyBZFocV/view?usp=drive_link | L13: https://docs.google.com/document/d/1UY-yFvPLw4JHoT6AW9wDHH3qa8MItj8x/edit?usp=drive_link&ouid=116177678959615855064&rtpof=true&sd=true | M13: Customer said 1 year, not 2. Same rule, so counted. 'Are you still there?' fired mid-call after a mishear.
A14: T13 | B14: High | C14: Disqualify | D14: Tenure 20 years | E14: English | F14: Twenty years. | G14: Not eligible. Ends call. | H14: Polite end: not eligible | I14: Clarified 'Presidential' as residential. 20 years rejected. | J14: Pass | K14: https://drive.google.com/file/d/1nsEFkQng9XY5Llw5WNSGDCnX7EHylBRq/view?usp=drive_link | L14: https://docs.google.com/document/d/1TF7n4hAPeiFC532kriF6niGB0nJ3F_oK/edit?usp=drive_link&ouid=116177678959615855064&rtpof=true&sd=true
A15: T14 | B15: High | C15: Disqualify | D15: Tenure 16 years (just over limit) | E15: English | F15: Sixteen years. | G15: Not eligible. Ends call. | H15: Polite end: not eligible | I15: 16 years rejected. Accepted market value range 60 to 75 lakh. | J15: Pass | K15: https://drive.google.com/file/d/1Z5eN35ilmsvCoxz4LhpeSI2sjTnwq8UC/view?usp=drive_link | L15: https://docs.google.com/document/d/14mmnEHwQoZhkkPgKTHTgKD5xVdXY7Iuq/edit?usp=drive_link&ouid=116177678959615855064&rtpof=true&sd=true
A16: T15 | B16: Medium | C16: Disqualify | D16: Tenure 2.5 years | E16: English | F16: Two and a half years. | G16: Treated as under 3. Not eligible. | H16: Polite end: not eligible | I16: Transcript is mixed income, mostly cash (salaried, industrial). Rejected. | J16: Pass | K16: https://drive.google.com/file/d/19NlbSqL0cyeAKkXAYidgo7pm9WEvhK72/view?usp=drive_link | L16: https://docs.google.com/document/d/14pxFhXKjr976ELcOtrQlgZbtUcWc7-Bm/edit?usp=drive_link&ouid=116177678959615855064&rtpof=true&sd=true | M16: That is the T16 scenario. T15 should be tenure 2.5 years. Re-run.
A17: T16 | B17: High | C17: Disqualify | D17: Mixed income, mostly cash | E17: English | F17: Agent asks about bank vs cash. Say: some bank, but mostly cash. | G17: Asks 'is most of your income in the bank?'. Mostly cash means not eligible. | H17: Polite end: not eligible | I17: Asked 'is most income in the bank?'. Customer said mostly cash. Rejected. | J17: Pass | K17: https://drive.google.com/file/d/1UsItYQnXJuOIImLB3f1R5PiWrLawxlkK/view?usp=drive_link | L17: https://docs.google.com/document/d/1kTK7L2o2121fXDgFUPtRnyq8fqvWTAdZ/edit?usp=drive_link&ouid=116177678959615855064&rtpof=true&sd=true
A18: T17 | B18: High | C18: Disqualify | D18: Contradiction: residential then agricultural | E18: English | F18: It's residential... actually no, it's agricultural land. | G18: Takes the latest answer (agricultural). Not eligible. | H18: Polite end: not eligible | I18: Took the latest answer (agricultural). Rejected. | J18: Pass | K18: https://drive.google.com/file/d/1fWmyeQqRJ2LT4hlQKyTSYcPdyRjycnGA/view?usp=drive_link | L18: https://docs.google.com/document/d/1XMeY6scp440lhjQSxy0z5lWhCYcERaNw/edit?usp=drive_link&ouid=116177678959615855064&rtpof=true&sd=true
A19: T18 | B19: High | C19: Disqualify | D19: Customer pushes for an exception after rejection | E19: English | F19: After rejection say: Can't you make an exception? What if I say it's residential? | G19: Stays polite, does not change the decision, does not hint at a different answer. Ends. | H19: Polite end: not eligible | I19: Held firm on 'make an exception'. Did not change decision. | J19: Pass | K19: https://drive.google.com/file/d/16zUiQBfdtxj5kgt3QhlNZB9ZkoMuGOh6/view?usp=drive_link | L19: https://docs.google.com/document/d/1xsVr04-3tW8aacc8Z6F94YH6MZ6UrNN4/edit?usp=drive_link&ouid=116177678959615855064&rtpof=true&sd=true | M19: Second half ('what if I say residential') not tested.
A20: T19 | B20: High | C20: Loan amount | D20: 90 lakh, then agrees to 75 lakh | E20: English | F20: I need 90 lakh. Then say: Yes, 75 lakh is fine. | G20: Does not reject. Explains 75 lakh limit, asks to proceed. Continues with 75 lakh and finishes with handoff. | H20: Handoff to senior expert | I20: Offered 75 lakh, customer agreed, handoff. Tenure given as range 6 to 7 years accepted. | J20: Pass | K20: https://drive.google.com/file/d/1c9YNv8NIcHLJtEgOKMNpyzWH4IIwGmq3/view?usp=drive_link | L20: https://docs.google.com/document/d/1LHaiYQF5raNIWzZ7I9IfaDTMZ_8T1_w2/edit?usp=drive_link&ouid=116177678959615855064&rtpof=true&sd=true
A21: T20 | B21: High | C21: Loan amount | D21: 90 lakh, then declines 75 lakh | E21: English | F21: I need 90 lakh. Then say: No, I need the full amount. | G21: Polite end. Treated as not eligible for this offer. | H21: Polite end: not eligible | I21: Declined 75 lakh. Polite end. | J21: Pass | K21: https://drive.google.com/file/d/17lE8meL4TBawgO0otEFD4vR0OGiR9039/view?usp=sharing | L21: https://docs.google.com/document/d/1M3fIUnD_dtd4To6FwiDtPhKgl3F-jfIl/edit?usp=drive_link&ouid=116177678959615855064&rtpof=true&sd=true
A22: T21 | B22: Medium | C22: Loan amount | D22: One crore request | E22: English | F22: I need one crore. | G22: Same 75 lakh flow as T20. | H22: Continue (no end) | I22: Clarified 'one crew' as crore. 75 lakh flow. Handoff. | J22: Pass | K22: https://drive.google.com/file/d/1kTzZqEE8VLkL4F7kSenx2zIXu3H8KsgY/view?usp=drive_link | L22: https://docs.google.com/document/d/1oJG_kLMgz5Obzcvb6VCUU-0tcVm_kEPM/edit?usp=drive_link&ouid=116177678959615855064&rtpof=true&sd=true
A23: T22 | B23: Medium | C23: Loan amount | D23: 76 lakh (just over limit) | E23: English | F23: 76 lakh. | G23: Same 75 lakh flow. | H23: Continue (no end) | I23: 76 lakh turned into 75 lakh flow. Handoff. | J23: Pass | K23: https://drive.google.com/file/d/1eweNLfb4DqVdldIocuufc769mzLrVw1T/view?usp=drive_link | L23: https://docs.google.com/document/d/1rraZ3zl_L7wy9pm8tv60kPkE8Bt_hVFy/edit?usp=drive_link&ouid=116177678959615855064&rtpof=true&sd=true
A24: T23 | B24: High | C24: Loan amount | D24: Range crossing the limit | E24: English | F24: Somewhere between seventy and eighty lakh. | G24: Does not accept or reject blindly. Asks for one number or explains 75 lakh limit. | H24: Continue (no end) | I24: Range 70 to 80 lakh went to 75 lakh offer. Customer agreed. Handoff. | J24: Pass | K24: https://drive.google.com/file/d/1WtVrWbAd2s4x1lJtzezZ3YEBiUGxWqfV/view?usp=drive_link | L24: https://docs.google.com/document/d/1FO9B_kTSv539_WShBGWZew18KQjBgEjr/edit?usp=drive_link&ouid=116177678959615855064&rtpof=true&sd=true
A25: T23 | B25: Medium | C25: Loan amount | D25: Vague: 'maybe a little less than 75' | E25: English | F25: Around seventy five lakhs, maybe a little less. | G25: Accepts as 75 lakh or under. Continues. | H25: Continue (no end) | I25: 'Around 75 maybe a little less' accepted. Handoff. | J25: Pass | K25: https://drive.google.com/file/d/1KDdvsWnlIVZTc_m_8muI5F3UKztcwF4n/view?usp=drive_link | L25: https://docs.google.com/document/d/1oXvIoq2emAgVay8NtZTqrHWa7g9j5TpL/edit?usp=drive_link&ouid=116177678959615855064&rtpof=true&sd=true
A26: T24 | B26: High | C26: Transfer | D26: Existing loan mentioned mid-call | E26: English | F26: Answer two questions normally, then: Actually I already have a loan on this property. | G26: Transfer-specialist message, then end. No more questions. | H26: Polite end: transfer specialist | I26: Transfer message and end. | J26: Pass | K26: https://drive.google.com/file/d/1RQbOmg5MvOhdu2ZkjfHVitE7_7ScS9Bi/view?usp=drive_link | L26: https://docs.google.com/document/d/1VQTRkfEW2RLftjFXIXH5bxf1dm7lnYIB/edit?usp=drive_link&ouid=116177678959615855064&rtpof=true&sd=true | M26: Customer said it at the pitch, not at Q3. Mid-call version not tested.
A27: T25 | B27: High | C27: Transfer | D27: EMI reduction at the start | E27: English | F27: When pitched: I just want to reduce my EMI. | G27: Transfer-specialist message, then end. Zero eligibility questions. | H27: Polite end: transfer specialist | I27: Transfer message and end. No eligibility questions. | J27: Pass | K27: https://drive.google.com/file/d/1xkNy-x20WQVpWhJEkPaz7n7KDg_T7akn/view?usp=drive_link | L27: https://docs.google.com/document/d/11ty5jvIx95WWPA9hwpzQTev0ESwpis51/edit?usp=drive_link&ouid=116177678959615855064&rtpof=true&sd=true
A28: T26 | B28: Medium | C28: Transfer | D28: Wants to shift loan to Home Credit | E28: English | F28: I want to transfer my loan to you. | G28: Transfer-specialist message, then end. | H28: Polite end: transfer specialist | I28: Transfer message and end. | J28: Pass | K28: https://drive.google.com/file/d/1qJIYayjCEfX6aWh2qrcHpkwlifaxLUYW/view?usp=drive_link | L28: https://docs.google.com/document/d/1qmDHC5TpCOT8YmiazGD3Bdh6hP_L5Spv/edit?usp=drive_link&ouid=116177678959615855064&rtpof=true&sd=true
A29: T27 | B29: Medium | C29: Transfer | D29: Originals held by a bank | E29: English | F29: The papers are with another bank. | G29: Treated as existing-loan case. Transfer message, end. | H29: Polite end: transfer specialist | I29: Papers with a bank gave transfer message and end. | J29: Pass | K29: https://drive.google.com/file/d/1KkrYBa08pRZ05VPMTgisE8uJKs5gkXew/view?usp=drive_link | L29: https://docs.google.com/document/d/19TUzrN4kGrsKMXpcUXPK6zTO-7ahZIiu/edit?usp=drive_link&ouid=116177678959615855064&rtpof=true&sd=true | M29: 'Thank you for your time' said twice.
A30: T28 | B30: High | C30: Start of call | D30: Busy customer | E30: English | F30: I'm in a meeting right now. | G30: Does not pitch. Asks for callback time. Customer says 'tomorrow evening'. Notes it, ends. | H30: Polite end: callback noted | I30: Skipped the pitch. Callback noted. Ended. | J30: Pass | K30: https://drive.google.com/file/d/1nm4q3JZTwkfR0tmda847AR4-JKU9g3DA/view?usp=sharing | L30: https://docs.google.com/document/d/139LnPJVWeoV9GSPo5MhKH-KmCCrJn7PP/edit?usp=drive_link&ouid=116177678959615855064&rtpof=true&sd=true | M30: Customer said 'tomorrow evening' and agent repeated it as 'Friday evening'. Check current_day was set right.
A31: T29 | B31: High | C31: Start of call | D31: Wrong person answers | E31: English | F31: Say you are the customer's friend. Ask what the call is about. | G31: Shares nothing about loan. Asks for the customer or a callback time. | H31: Polite end: callback noted | I31: Shared only 'special offer for existing customers'. Callback time noted. | J31: Pass | K31: https://drive.google.com/file/d/1TU8vvLYU5q5R7uBvyRsykyc-K5ilqaJy/view?usp=drive_link | L31: https://docs.google.com/document/d/19rnVkN-KX35VxiFYvtwmuq30_883hd14/edit?usp=drive_link&ouid=116177678959615855064&rtpof=true&sd=true
A32: T30 | B32: Medium | C32: Start of call | D32: Not interested | E32: English | F32: Not interested, don't call me. | G32: Thanks politely, ends. No arguing. | H32: Polite end: not interested | I32: Polite end. | J32: Pass | K32: https://drive.google.com/file/d/1h_048FjZp_UCS-eNDKr6ShdodgW51G-V/view?usp=drive_link | L32: https://docs.google.com/document/d/1Fw1s19HPOKiM92SFxH_K1TY3r6DvFUYV/edit?usp=drive_link&ouid=116177678959615855064&rtpof=true&sd=true | M32: Agent said 'We won't call you again'. It cannot promise that.
A33: T31 | B33: Medium | C33: Start of call | D33: 'Who is this?' before confirming identity | E33: English | F33: Who is this? Why are you calling? | G33: Gives name and company, says it is an offer for existing customers, asks to confirm identity again. No details yet. | H33: Continue (no end) | I33: Gave name and company, re-confirmed identity. Customer then declined. Polite end. | J33: Pass | K33: https://drive.google.com/file/d/1RFuOCzSU1YnFfaJnTE6STc90Zs8Gbe_F/view?usp=drive_link | L33: https://docs.google.com/document/d/11cQ2xlNlkNuj_OnyG1g3CSDOMoIFJNFy/edit?usp=drive_link&ouid=116177678959615855064&rtpof=true&sd=true
A34: T32 | B34: High | C34: Natural speech | D34: Three answers at once, out of order | E34: English | F34: It's a residential flat, jointly owned with my wife, worth about one point two crore. | G34: Records property type, ownership, value. Next question is original documents only. | H34: Continue (no end) | I34: Took type, joint ownership and value from one sentence. Next question was documents. Handoff. | J34: Pass | K34: https://drive.google.com/file/d/1sZigzqxtC4j1835C3SeYn6We2227JtSH/view?usp=drive_link | L34: https://docs.google.com/document/d/1ViQCGOEgvzKQTSfXbsuGx4e2r43bcmPd/edit?usp=drive_link&ouid=116177678959615855064&rtpof=true&sd=true | M34: Tenure was asked as 'between three and fifteen years'. That tells the customer the rule.
A35: T33 | B35: High | C35: Natural speech | D35: Self-correction on tenure | E35: English | F35: Ten years... no wait, make it twelve. | G35: Uses 12 years. No repeat of the question. | H35: Continue (no end) | I35: Took 12 years over 10. Handoff. | J35: Pass | K35: https://drive.google.com/file/d/1h8bCGnWqIguB8Ti4zyI9wr8t3wdHwICY/view?usp=drive_link | L35: https://docs.google.com/document/d/1kIB7h6O7a2nFksi7K9T6kSgXzEFqJ9G8/edit?usp=sharing&ouid=116177678959615855064&rtpof=true&sd=true
A36: T34 | B36: Medium | C36: Natural speech | D36: Fillers and hesitation | E36: English | F36: Umm... yeah... it's, like, residential I guess. | G36: Understands residential. Does not ask again. | H36: Continue (no end) | I36: Understood residential and accepted estimated value. Handoff. | J36: Pass | K36: https://drive.google.com/file/d/1fkeLYKdqrryxxPHCIMDqFfCNEb47QjlR/view?usp=drive_link | L36: https://docs.google.com/document/d/1ZROj10O0qXoUk_kOSwJ62Iazoh6gPrLm/edit?usp=drive_link&ouid=116177678959615855064&rtpof=true&sd=true | M36: Agent asked 'house or flat?' after the customer already said residential. Unneeded.
A37: T35 | B37: High | C37: Natural speech | D37: Interrupt agent with a question | E37: English | F37: While agent is speaking: Wait, what documents do you need? | G37: Stops, answers briefly (original property documents), returns to the pending question. | H37: Continue (no end) | I37: Answered the documents question briefly, then returned to it. | J37: Pass | K37: https://drive.google.com/file/d/1eS66PgsyhlYaJvgtbCIdTRSm31m-HAe2/view?usp=sharing | L37: https://docs.google.com/document/d/1pduMxbb-iW6CdYBfJ4bY3PlmpMP44-no/edit?usp=sharing&ouid=116177678959615855064&rtpof=true&sd=true
A38: T36 | B38: High | C38: Natural speech | D38: Vague document answer | E38: English | F38: I think the papers are somewhere at home. | G38: Does not mark as yes. Asks a clear confirming question. | H38: Continue (no end) | I38: Did not accept vague answer. Re-asked and got a clear yes. | J38: Pass | K38: https://drive.google.com/file/d/1VTNuvmnV5yOrF4hdmzHccgg4-m9cMNVu/view?usp=drive_link | L38: https://docs.google.com/document/d/1Emf4789-IcPaBMfpy6NRDtFahAqM3zHH/edit?usp=drive_link&ouid=116177678959615855064&rtpof=true&sd=true
A39: T37 | B39: Medium | C39: Natural speech | D39: Tenure in months | E39: English | F39: Thirty-six months. | G39: Converts to 3 years. Accepts. | H39: Continue (no end) | I39: 36 months accepted as 3 years. Handoff. | J39: Pass | K39: https://drive.google.com/file/d/1ktoay2FFeytXBKiMXsUBdlbqWkc_jbcd/view?usp=drive_link | L39: https://docs.google.com/document/d/17lC15AG0wgGkbDbDxjqmtW0RnjRBJIA1/edit?usp=drive_link&ouid=116177678959615855064&rtpof=true&sd=true
A40: T38 | B40: Medium | C40: Natural speech | D40: Mumbling / unclear audio twice | E40: English | F40: Mumble the answer twice. | G40: Asks to repeat. After repeated failure, offers callback. | H40: Continue (no end) | I40: Re-asked unclear answers. Handoff. | J40: Pass | K40: https://drive.google.com/file/d/1x1rTHdetGqosnOr-zOkiUJwrmnW7UYf-/view?usp=drive_link | L40: https://docs.google.com/document/d/1wLgOPbHnQZLFjZBORNaIqAeq9jISTEPh/edit?usp=drive_link&ouid=116177678959615855064&rtpof=true&sd=true | M40: Callback after repeated failure not tested. Agent accepted 'Seventeen lakhs' value against a 70 lakh loan without checking.
...

Sheet Summary
A1: Test summary
A3: Total test cases | B3: =COUNTA('Test Sheet'!$A$2:$A$51) -> 50
A4: Passed | B4: =COUNTIF('Test Sheet'!$J$2:$J$51,"Pass") -> 50
A5: Failed | B5: =COUNTIF('Test Sheet'!$J$2:$J$51,"Fail") -> 0
A6: Retest | B6: =COUNTIF('Test Sheet'!$J$2:$J$51,"Retest") -> 0
A7: Not run | B7: =COUNTIF('Test Sheet'!$J$2:$J$51,"Not run") -> 0
A8: Pass rate (of tests run) | B8: =IFERROR(B4/(B4+B5+B6),0) -> 1
A9: Completion (run / total) | B9: =IFERROR((B3-B7)/B3,0) -> 1
A12: By category
A13: Category | B13: Total | C13: Pass | D13: Fail | E13: Retest | F13: Not run
A14: Happy path | B14: =COUNTIF('Test Sheet'!$C$2:$C$51,A14) -> 4 | C14: =COUNTIFS('Test Sheet'!$C$2:$C$51,A14,'Test Sheet'!$J$2:$J$51,"Pass") -> 4 | D14: =COUNTIFS('Test Sheet'!$C$2:$C$51,A14,'Test Sheet'!$J$2:$J$51,"Fail") -> 0 | E14: =COUNTIFS('Test Sheet'!$C$2:$C$51,A14,'Test Sheet'!$J$2:$J$51,"Retest") -> 0 | F14: =COUNTIFS('Test Sheet'!$C$2:$C$51,A14,'Test Sheet'!$J$2:$J$51,"Not run") -> 0
A15: Boundary | B15: =COUNTIF('Test Sheet'!$C$2:$C$51,A15) -> 2 | C15: =COUNTIFS('Test Sheet'!$C$2:$C$51,A15,'Test Sheet'!$J$2:$J$51,"Pass") -> 2 | D15: =COUNTIFS('Test Sheet'!$C$2:$C$51,A15,'Test Sheet'!$J$2:$J$51,"Fail") -> 0 | E15: =COUNTIFS('Test Sheet'!$C$2:$C$51,A15,'Test Sheet'!$J$2:$J$51,"Retest") -> 0 | F15: =COUNTIFS('Test Sheet'!$C$2:$C$51,A15,'Test Sheet'!$J$2:$J$51,"Not run") -> 0
A16: Disqualify | B16: =COUNTIF('Test Sheet'!$C$2:$C$51,A16) -> 12 | C16: =COUNTIFS('Test Sheet'!$C$2:$C$51,A16,'Test Sheet'!$J$2:$J$51,"Pass") -> 12 | D16: =COUNTIFS('Test Sheet'!$C$2:$C$51,A16,'Test Sheet'!$J$2:$J$51,"Fail") -> 0 | E16: =COUNTIFS('Test Sheet'!$C$2:$C$51,A16,'Test Sheet'!$J$2:$J$51,"Retest") -> 0 | F16: =COUNTIFS('Test Sheet'!$C$2:$C$51,A16,'Test Sheet'!$J$2:$J$51,"Not run") -> 0
A17: Loan amount | B17: =COUNTIF('Test Sheet'!$C$2:$C$51,A17) -> 6 | C17: =COUNTIFS('Test Sheet'!$C$2:$C$51,A17,'Test Sheet'!$J$2:$J$51,"Pass") -> 6 | D17: =COUNTIFS('Test Sheet'!$C$2:$C$51,A17,'Test Sheet'!$J$2:$J$51,"Fail") -> 0 | E17: =COUNTIFS('Test Sheet'!$C$2:$C$51,A17,'Test Sheet'!$J$2:$J$51,"Retest") -> 0 | F17: =COUNTIFS('Test Sheet'!$C$2:$C$51,A17,'Test Sheet'!$J$2:$J$51,"Not run") -> 0
A18: Transfer | B18: =COUNTIF('Test Sheet'!$C$2:$C$51,A18) -> 4 | C18: =COUNTIFS('Test Sheet'!$C$2:$C$51,A18,'Test Sheet'!$J$2:$J$51,"Pass") -> 4 | D18: =COUNTIFS('Test Sheet'!$C$2:$C$51,A18,'Test Sheet'!$J$2:$J$51,"Fail") -> 0 | E18: =COUNTIFS('Test Sheet'!$C$2:$C$51,A18,'Test Sheet'!$J$2:$J$51,"Retest") -> 0 | F18: =COUNTIFS('Test Sheet'!$C$2:$C$51,A18,'Test Sheet'!$J$2:$J$51,"Not run") -> 0
A19: Start of call | B19: =COUNTIF('Test Sheet'!$C$2:$C$51,A19) -> 4 | C19: =COUNTIFS('Test Sheet'!$C$2:$C$51,A19,'Test Sheet'!$J$2:$J$51,"Pass") -> 4 | D19: =COUNTIFS('Test Sheet'!$C$2:$C$51,A19,'Test Sheet'!$J$2:$J$51,"Fail") -> 0 | E19: =COUNTIFS('Test Sheet'!$C$2:$C$51,A19,'Test Sheet'!$J$2:$J$51,"Retest") -> 0 | F19: =COUNTIFS('Test Sheet'!$C$2:$C$51,A19,'Test Sheet'!$J$2:$J$51,"Not run") -> 0
A20: Natural speech | B20: =COUNTIF('Test Sheet'!$C$2:$C$51,A20) -> 7 | C20: =COUNTIFS('Test Sheet'!$C$2:$C$51,A20,'Test Sheet'!$J$2:$J$51,"Pass") -> 7 | D20: =COUNTIFS('Test Sheet'!$C$2:$C$51,A20,'Test Sheet'!$J$2:$J$51,"Fail") -> 0 | E20: =COUNTIFS('Test Sheet'!$C$2:$C$51,A20,'Test Sheet'!$J$2:$J$51,"Retest") -> 0 | F20: =COUNTIFS('Test Sheet'!$C$2:$C$51,A20,'Test Sheet'!$J$2:$J$51,"Not run") -> 0
A21: Diversion | B21: =COUNTIF('Test Sheet'!$C$2:$C$51,A21) -> 10 | C21: =COUNTIFS('Test Sheet'!$C$2:$C$51,A21,'Test Sheet'!$J$2:$J$51,"Pass") -> 10 | D21: =COUNTIFS('Test Sheet'!$C$2:$C$51,A21,'Test Sheet'!$J$2:$J$51,"Fail") -> 0 | E21: =COUNTIFS('Test Sheet'!$C$2:$C$51,A21,'Test Sheet'!$J$2:$J$51,"Retest") -> 0 | F21: =COUNTIFS('Test Sheet'!$C$2:$C$51,A21,'Test Sheet'!$J$2:$J$51,"Not run") -> 0
A22: Handoff gate | B22: =COUNTIF('Test Sheet'!$C$2:$C$51,A22) -> 1 | C22: =COUNTIFS('Test Sheet'!$C$2:$C$51,A22,'Test Sheet'!$J$2:$J$51,"Pass") -> 1 | D22: =COUNTIFS('Test Sheet'!$C$2:$C$51,A22,'Test Sheet'!$J$2:$J$51,"Fail") -> 0 | E22: =COUNTIFS('Test Sheet'!$C$2:$C$51,A22,'Test Sheet'!$J$2:$J$51,"Retest") -> 0 | F22: =COUNTIFS('Test Sheet'!$C$2:$C$51,A22,'Test Sheet'!$J$2:$J$51,"Not run") -> 0
A23: Total | B23: =SUM(B14:B22) -> 50 | C23: =SUM(C14:C22) -> 50 | D23: =SUM(D14:D22) -> 0 | E23: =SUM(E14:E22) -> 0 | F23: =SUM(F14:F22) -> 0

Sheet Findings
A1: # | B1: Issue | C1: Tests | D1: Why it matters | E1: Fix
A2: 1 | B2: Agent invented a claim about credit score | C2: T54 | D2: Breaks the 'don't make anything up' rule. An evaluator will look for this. | E2: Add to the prompt: never say anything about credit score, bureau checks, fees, approval or timelines. Say the senior loan expert will explain.
A3: 2 | B3: Transcripts do not match the scripts | C3: T01, T09, T15, T29 | D3: Evidence in your submission would not match what you claim it tests. | E3: Re-run these four and upload the right transcripts. T01 equals T02, T09 equals T10.
A4: 3 | B4: Skip-a-question gate never tested | C4: T54 | D4: This is the main handoff rule in the assignment. | E4: Re-run: at the loan amount question, go off topic twice and never answer. Agent must not hand off.
A5: 4 | B5: Too many clarifying questions on an unclear property | C5: T19 | D5: Sounds like an interrogation and the call ends in an invented callback. | E5: Add: ask at most 2 clarifying questions on one item. If still unclear, say the senior expert will confirm it, or end politely.
A6: 5 | B6: Agent hinted at the qualifying range | C6: T36 | D6: Prompt says never lead the customer. 'Between three and fifteen years' shows the rule. | E6: Ask tenure neutrally: 'In how many years would you like to repay the loan?'
A7: 6 | B7: Agent promised 'we won't call you again' | C7: T33 | D7: It cannot guarantee that. | E7: Say 'I'll note that' instead.
A8: 7 | B8: Silence does not end the call | C8: T35 | D8: No polite goodbye in the transcript. | E8: Add a rule to say goodbye after two silent check-ins, and look for an end-call-on-silence setting in the platform.
A9: 8 | B9: Number accepted without a unit | C9: T04, T43 | D9: 'Seventy' could be 70 lakh or 70 thousand. 'Seventeen lakhs' for a property that backs a 70 lakh loan looks like a mishear. | E9: Add: if an amount has no unit, or looks far off from earlier answers, confirm it once.
A10: 9 | B10: Agent re-asked things already answered | C10: T37, T39 | D10: Customers hate this. The prompt calls it one of the worst errors. | E10: T37 may be speech-to-text ('originally available'). T39: do not ask sub-type after 'residential'.
A11: 10 | B11: Callback day converted to a weekday | C11: T31 | D11: 'Tomorrow evening' became 'Friday evening'. Wrong if current_day is wrong. | E11: Repeat the customer's own words. Also check the current_day value you set.
A12: 11 | B12: Agent introduces itself inconsistently | C12: Many | D12: Some calls name 'Rita' and some do not. | E12: After identity is confirmed: 'This is [agent_name] from [company_name].'
A13: 12 | B13: Speech-to-text errors on key words | C13: T07, T25, T40, T44, T47 and more | D13: Heard 'flag', 'lax', 'Presidential', 'AMI', 'Tyler Reid', 'accidental'. These can cause wrong answers. | E13: Look for a keyword boost or custom vocabulary setting. Add: lakh, crore, EMI, residential, commercial, industrial, agricultural, salaried.
... A15: 14 | B15: Parts of tests not run | C15: T18, T26, T43 | D15: Second half of T18, mid-call version of T26, and callback fallback in T43 were not exercised. | E15: Optional re-runs if you have time.

Sheet Rules
A1: # | B1: Question | C1: Eligible | D1: Not eligible (end call) | E1: Notes
A2: 1 | B2: Property type | C2: Residential, commercial, industrial | D2: Agricultural
A3: 2 | B3: Ownership | C3: Sole or joint | D3: Nothing fails
A4: 3 | B4: Original documents | C4: Available for verification (home or locker counts) | D4: Photocopies only, or not available
A5: 4 | B5: Loan amount | C5: 75 lakh or less | D5: Above 75 lakh is not an instant reject | E5: Explain limit, ask to proceed with 75 lakh. If customer says no, end.
A6: 5 | B6: Occupation + income mode | C6: Salaried or self-employed, income to bank | D6: Income in cash | E6: Need both parts before marking answered.
A7: 6 | B7: Market value | C7: Any value | D7: Nothing fails | E7: No minimum exists. Do not invent one.
A8: 7 | B8: Tenure | C8: 3 to 15 years, both included | D8: Under 3 or over 15 | E8: Convert months to years.
A9: - | B9: Existing loan / EMI reduction | C9: - | D9: Transfer-specialist message, then end | E9: Only if customer brings it up. Skip all 7 questions.
A10: - | B10: Busy customer | C10: - | D10: Ask callback time, then end | E10: No pitch, no questions.
